Workbook
Name _56F9DC9755BA473782653E2940F9FormId: "eLGl-_E6IESWa79RY-ax2iuoN7rWI-dLhfbHv3sOlYFUM0Y0RTFLQTE3WUtYV1pQOTgwNUEySkFJSiQlQCN0PWcu"
Name _56F9DC9755BA473782653E2940F9ResponseSheet: "Form1"
Name _56F9DC9755BA473782653E2940F9SourceDocId: "{f62d1b90-5b8b-47b9-9246-cc08b8118503}"

Sheet SEC.EXEC.
A1: ACOMPANHAMENTO EXECUÇÃO GESTÃO - 2024
A2: UNIDADE | B2: AÇÃO | C2: PO | D2: INICIATIVAS | E2: GRUPO DE DESPESAS | F2: DOTAÇÃO ATUALIZADA | G2: PROGRAMADO 2024 | H2: EMPENHADO 2024 | I2: LIQUIDADO 2024 | J2: PAGO 2024 | K2: OBSERVAÇÃO (PENDÊNCIAS)
A4: SECRETARIA EXECUTIVA | B4: 2000 | C4: 0000 | D4: Administração da unidade- Despesas diversas | E4: Despesas correntes | F4: 18899295 | G4: 18899295 | H4: 17466044 | I4: 10669894 | J4: 10420389 | K4: A pedido do CCAL, foi realizada uma troca de PO do 0000 para o 000B no valor de 400 mil As programações dos dois POS devem ser ajustadas para refletir a dotação existente (R$ 175.674,00 utilizados para Diaspora)
B5: 2000 | C5: 0000 | E5: Investimento | F5: 200000 | G5: 200000 | H5: 11925 | I5: 11925 | J5: 11925
B6: Subtotal PO 0000 | F6: =SUBTOTAL(109,F4:F5) -> 19099295 | G6: =SUBTOTAL(109,G4:G5) -> 19099295 | H6: =SUBTOTAL(109,H4:H5) -> 17477969 | I6: =SUBTOTAL(109,I4:I5) -> 10681819 | J6: =SUBTOTAL(109,J4:J5) -> 10432314
B7: 2000 | C7: 0007 | D7: Capacitação de Servidores Públicos Federais em Processo de Qualificação e Requalificação | E7: Despesas correntes | F7: 317309 | G7: 317309 | H7: 288403.67 | I7: 132525.97 | J7: 132525.97 | K7: Previsão de gastos até o fim de 2024, com cursos de idiomas, congressos, GECC, dentre outros. Fazer num pedido de recomposição de R$182.691 devido ao remanejamento realizado em julho
B8: Subtotal PO 0007 | F8: =SUBTOTAL(109,F7) -> 317309 | G8: =SUBTOTAL(109,G7) -> 317309 | H8: =SUBTOTAL(109,H7) -> 288403.67 | I8: =SUBTOTAL(109,I7) -> 132525.97 | J8: =SUBTOTAL(109,J7) -> 132525.97
B9: 2000 | C9: 000B | D9: Ajuda de custo (mobilização e desmobilização) | E9: Despesas correntes | F9: 642128 | G9: 642128 | H9: 318961.74 | I9: 279889.08 | J9: 279889.08 | K9: Ajuste do valor tendo em vistas novas nomeações/exonerações
B10: Subtotal PO 000B | F10: =SUBTOTAL(109,F9) -> 642128 | G10: =SUBTOTAL(109,G9) -> 642128 | H10: =SUBTOTAL(109,H9) -> 318961.74 | I10: =SUBTOTAL(109,I9) -> 279889.08 | J10: =SUBTOTAL(109,J9) -> 279889.08
B11: 2000 | C11: 000C | D11: Ajuda de custo para Estagiários | E11: Despesas correntes | F11: 275980 | G11: 275980 | H11: 220673 | I11: 176534.71 | J11: 149203.18 | K11: Valor para pagamento de bolsas de estágiarios até o final de 2024
B12: Subtotal PO 000C | F12: =SUBTOTAL(109,F11) -> 275980 | G12: =SUBTOTAL(109,G11) -> 275980 | H12: =SUBTOTAL(109,H11) -> 220673 | I12: =SUBTOTAL(109,I11) -> 176534.71 | J12: =SUBTOTAL(109,J11) -> 149203.18
B13: 2000 | C13: 000F | D13: Integração e Aquisição de Tecnologia da Informação | E13: Despesas correntes | F13: 1184630 | G13: 758630 | H13: 522239.82 | I13: 343712.07 | J13: 343712.07
B14: 2000 | C14: 000F | E14: Investimento | F14: 200000 | G14: 200000
B15: Subtotal PO 000F | F15: =SUBTOTAL(109,F13:F14) -> 1384630 | G15: =SUBTOTAL(109,G13:G14) -> 958630 | H15: =SUBTOTAL(109,H13:H14) -> 522239.82 | I15: =SUBTOTAL(109,I13:I14) -> 343712.07 | J15: =SUBTOTAL(109,J13:J14) -> 343712.07
B16: 2000 | C16: 0010 | D16: Conservação de Ativos da União | E16: Despesas correntes | F16: 0 | K16: Valor integral oferecido para cancelamento
B17: Subtotal PO 0010 | F17: =SUBTOTAL(109,F16) -> 0 | G17: =SUBTOTAL(109,G16) -> 0 | H17: =SUBTOTAL(109,H16) -> 0 | I17: =SUBTOTAL(109,I16) -> 0 | J17: =SUBTOTAL(109,J16) -> 0
B18: Subtotal Ação 2000 | F18: =SUBTOTAL(109,F4:F17) -> 21719342 | G18: =SUBTOTAL(109,G4:G17) -> 21293342 | H18: =SUBTOTAL(109,H4:H17) -> 18828247 | I18: =SUBTOTAL(109,I4:I17) -> 11614481 | J18: =SUBTOTAL(109,J4:J17) -> 11337644
B19: 216h | C19: 0000 | D19: Auxilio Moradia servidores publicos | E19: Despesas Correntes | F19: 1408000 | G19: 1408000 | H19: 1408000 | I19: 839440.91 | J19: 759653.77
B20: Subtotal Ação 216H | F20: =SUBTOTAL(109,F19) -> 1408000 | G20: =SUBTOTAL(109,G19) -> 1408000 | H20: =SUBTOTAL(109,H19) -> 1408000 | I20: =SUBTOTAL(109,I19) -> 839440.91 | J20: =SUBTOTAL(109,J19) -> 759653.77
B21: 4641 | C21: 0000 | D21: Publicidade de Utilidade Pública | E21: Despesas correntes | F21: 454769
B22: Subtotal Ação 4641 | F22: =SUBTOTAL(109,F21) -> 454769 | G22: =SUBTOTAL(109,G21) -> 0 | H22: =SUBTOTAL(109,H21) -> 0 | I22: =SUBTOTAL(109,I21) -> 0 | J22: =SUBTOTAL(109,J21) -> 0
B23: 162G | C23: 0000 | D23: Exercício da Presidência do G20 pelo Brasil | E23: Despesas correntes | F23: 919593 | G23: 919593 | H23: 919593 | I23: 919593 | J23: 919593
B24: Subtotal Ação 162G | F24: =SUBTOTAL(109,F23) -> 919593 | G24: =SUBTOTAL(109,G23) -> 919593 | H24: =SUBTOTAL(109,H23) -> 919593 | I24: =SUBTOTAL(109,I23) -> 919593 | J24: =SUBTOTAL(109,J23) -> 919593
B25: TOTAL | F25: =SUBTOTAL(109,F4:F24) -> 24501704 | G25: =SUBTOTAL(109,G4:G24) -> 23620935 | H25: =SUBTOTAL(109,H4:H24) -> 21155840 | I25: =SUBTOTAL(109,I4:I24) -> 13373515 | J25: =SUBTOTAL(109,J4:J24) -> 13016891
B26: (%) DE EXECUÇÃO | F26: =H25/F25 -> 0.86344362

Sheet LIMITE DE MOVIMENTAÇÃO EMPENHO
A1: LIMITE | B1: AGUARDANDO EMPENHO | C1: EMPENHADO | D1: LIMITE CONSUMIDO | E1: EMPENHADO/ LIMITE | G1: LIMITE A CONSUMIR
A2: =72484603+20809690+34248+15853095 -> 109181636 | B2: ='Consolidado 2026'!C4 -> 1516590.6 | C2: ='Consolidado 2026'!D4 -> 1.0042509e+08 | D2: =B2+C2 -> 1.0194168e+08 | E2: =C2/A2 -> 0.91979832 | G2: =A2-D2 -> 7239960

Sheet Consolidado 2026
A1: LIMITE DE MOVIMENTAÇÃO EMPENHO
A2: Decreto nº 12.990, de 29 de maio de 2026, e alterações | B2: ATÉ NOVEMBRO 2026
B3: LIMITE | C3: AGUARDANDO EMPENHO | D3: EMPENHADO | E3: LIMITE CONSUMIDO | F3: EMPENHADO/ LIMITE | H3: LIMITE A CONSUMIR
A4: MIR | B4: =72484603+20809690+34248+15853095 -> 109181636 | C4: =K10 -> 1516590.6 | D4: =L10 -> 1.0042509e+08 | E4: =C4+D4 -> 1.0194168e+08 | F4: =D4/B4 -> 0.91979832 | H4: =B4-E4 -> 7239960
A5: O LME refere-se ao montante autorizado por decreto para execução pelo MIR em determinado período do exercício. Dessa forma, as áreas devem observar, no planejamento de suas ações, a capacidade de execução orçamentária disponível para o Ministério no respectivo período.
L7: Atualização: 21/10/2026 (base SIAFI) | U7: Planilha | V7: Código | W7: PROGRAMADO 2025 | X7: EMPENHADO 2025 | Y7: LIQUIDADO 2025 | Z7: PAGO 2025
A8: PROGRAMAÇÃO | B8: GND | C8: PLOA | D8: LOA | E8: DOTAÇÃO ATUALIZADA 2026 | F8: BLOQUEIO DECRETO Nº 12.990 | G8: BLOQUEIO SOF/MPO | H8: DOTAÇÃO LIVRE PARA EMPENHO | I8: PROGRAMADO 2026 | J8: DESCENTRALIZADO (ocultar) | K8: DESCENTRALIZADO (ainda não empenhado) 2026 | L8: EMPENHADO 2026 | M8: LIQUIDADO 2026 | N8: PAGO 2026 | O8: SALDO A UTILIZAR 2026 | P8: (%) Programado | Q8: (%) Empenhado | R8: (%) Liquidado | S8: (%) Pago | W8: L3:L200 | X8: M3:M200 | Y8: N3:N200 | Z8: O3:O200
A10: TOTAL GERAL | C10: =SUBTOTAL(109,C12:C58) -> 170823603 | D10: =SUBTOTAL(109,D12:D58) -> 158737644 | E10: =SUBTOTAL(109,E12:E58) -> 158801726 | F10: =SUBTOTAL(109,F12:F58) -> 29876127 | G10: =SUBTOTAL(109,G12:G58) -> 0 | H10: =SUBTOTAL(109,H12:H58) -> 128925599 | I10: =SUBTOTAL(109,I12:I58) -> 1.3014019e+08 | J10: =SUBTOTAL(109,J12:J58) -> 1.0194168e+08 | ... O10: =SUBTOTAL(109,O12:O58) -> 26983923 | P10: =I10/H10 -> 1.0094208 | Q10: =L10/H10 -> 0.77893829 | R10: =M10/H10 -> 0.58845527 | S10: =N10/H10 -> 0.54894257
A12: SEPAR | C12: =SUBTOTAL(109,C13:C20) -> 42164656 | D12: =SUBTOTAL(109,D13:D20) -> 39175588 | E12: =SUBTOTAL(109,E13:E20) -> 39175588 | F12: =SUBTOTAL(109,F13:F20) -> 7660000 | G12: =SUBTOTAL(109,G13:G20) -> 0 | H12: =SUBTOTAL(109,H13:H20) -> 31515588 | I12: =SUBTOTAL(109,I13:I20) -> 31176620 | J12: =SUBTOTAL(109,J13:J19) -> 22587910 | K12: =SUBTOTAL(109,K13:K19) -> 137620.28 | L12: =SUBTOTAL(109,L13:L20) -> 23971440 | M12: =SUBTOTAL(109,M13:M20) -> 19285180 | N12: =SUBTOTAL(109,N13:N20) -> 18345219 | O12: =SUBTOTAL(109,O13:O20) -> 7406527.7 | P12: =I12/H12 -> 0.98924445 | Q12: =L12/H12 -> 0.7606217 | R12: =M12/H12 -> 0.61192513 | S12: =N12/H12 -> 0.58209984
A13: 21HN - Gestão de Políticas de Ações Afirmativas e de Combate e Superação do Racismo | C13: =SUBTOTAL(109,C14:C16) -> 26656612 | D13: =SUBTOTAL(109,D14:D16) -> 24703694 | E13: =SUBTOTAL(109,E14:E16) -> 28703694 | F13: =SUBTOTAL(109,F14:F16) -> 3572084 | G13: =SUBTOTAL(109,G14:G16) -> 0 | H13: =SUBTOTAL(109,H14:H16) -> 25131610 | I13: =SUBTOTAL(109,I14:I16) -> 24802643 | J13: =SUBTOTAL(109,J14:J16) -> 20837910 | ... O13: =SUBTOTAL(109,O14:O16) -> 4293699.7 | P13: =I13/H13 -> 0.98691023 | Q13: =L13/H13 -> 0.82367545 | R13: =M13/H13 -> 0.69689184 | S13: =N13/H13 -> 0.65949028
A14: 0000 - Gestão de Políticas de Ações Afirmativas e de Combate e Superação do Racismo - Despesas Diversas | B14: Despesas correntes | C14: 1500000 | D14: 1390108 | E14: 560000 | F14: 0 | H14: =E14-G14-F14 -> 560000 | I14: =SUMIFS(INDIRECT($U14 & W$8),INDIRECT($U14 & "B3:B200"),$V14,INDIRECT($U14 & "D3:D200"),$B14) -> 560000 | J14: 560000 | L14: =SUMIFS(INDIRECT($U14 & X$8),INDIRECT($U14 & "B3:B200"),$V14,INDIRECT($U14 & "D3:D200"),$B14) -> 560000 | M14: =SUMIFS(INDIRECT($U14 & Y$8),INDIRECT($U14 & "B3:B200"),$V14,INDIRECT($U14 & "D3:D200"),$B14) -> 304630.96 | N14: =SUMIFS(INDIRECT($U14 & Z$8),INDIRECT($U14 & "B3:B200"),$V14,INDIRECT($U14 & "D3:D200"),$B14) -> 304630.96 | O14: =H14-K14-L14 -> 0 | P14: =I14/H14 -> 1 | Q14: =L14/H14 -> 1 | R14: =M14/H14 -> 0.54398386 | S14: =N14/H14 -> 0.54398386 | U14: '21HN - SEPAR'! | V14: =IF(A14="",LEFT(A13,4),LEFT(A14,4)) -> 0000
A15: 0001 - Fortalecimento das Ações Afirmativas | B15: Despesas correntes | C15: 12578306 | D15: 11656793 | E15: 8522424 | F15: 2960000 | H15: =E15-G15-F15 -> 5562424 | I15: =SUMIFS(INDIRECT($U15 & W$8),INDIRECT($U15 & "B3:B200"),$V15,INDIRECT($U15 & "D3:D200"),$B15) -> 5562423.9 | J15: 1661216.4 | K15: =J15-L15 -> 51145.44 | L15: =SUMIFS(INDIRECT($U15 & X$8),INDIRECT($U15 & "B3:B200"),$V15,INDIRECT($U15 & "D3:D200"),$B15) -> 1610071 | M15: =SUMIFS(INDIRECT($U15 & Y$8),INDIRECT($U15 & "B3:B200"),$V15,INDIRECT($U15 & "D3:D200"),$B15) -> 651016.41 | N15: =SUMIFS(INDIRECT($U15 & Z$8),INDIRECT($U15 & "B3:B200"),$V15,INDIRECT($U15 & "D3:D200"),$B15) -> 456115.81 | O15: =H15-K15-L15 -> 3901207.6 | P15: =I15/H15 -> 0.99999998 | Q15: =L15/H15 -> 0.28945492 | R15: =M15/H15 -> 0.11703826 | S15: =N15/H15 -> 0.081999468 | U15: '21HN - SEPAR'! | V15: =IF(A15="",LEFT(A14,4),LEFT(A15,4)) -> 0001
A16: 0002 - Promoção e Implementação de Políticas para o Combate e a Superação de todas as Formas de Racismo | B16: Despesas correntes | C16: 12578306 | D16: 11656793 | E16: 19621270 | F16: 612084 | H16: =E16-G16-F16 -> 19009186 | I16: =SUMIFS(INDIRECT($U16 & W$8),INDIRECT($U16 & "B3:B200"),$V16,INDIRECT($U16 & "D3:D200"),$B16) -> 18680219 | J16: 18616694 | K16: =J16-L16 -> 86474.84 | L16: =SUMIFS(INDIRECT($U16 & X$8),INDIRECT($U16 & "B3:B200"),$V16,INDIRECT($U16 & "D3:D200"),$B16) -> 18530219 | M16: =SUMIFS(INDIRECT($U16 & Y$8),INDIRECT($U16 & "B3:B200"),$V16,INDIRECT($U16 & "D3:D200"),$B16) -> 16558366 | N16: =SUMIFS(INDIRECT($U16 & Z$8),INDIRECT($U16 & "B3:B200"),$V16,INDIRECT($U16 & "D3:D200"),$B16) -> 15813306 | O16: =H16-K16-L16 -> 392492.07 | P16: =I16/H16 -> 0.98269432 | Q16: =L16/H16 -> 0.9748034 | R16: =M16/H16 -> 0.87107183 | S16: =N16/H16 -> 0.83187706 | U16: '21HN - SEPAR'! | V16: =IF(A16="",LEFT(#REF!,4),LEFT(A16,4)) -> 0002
A17: 21FF - Fortalecimento de Políticas em prol da Vida e do Bem Viver da Juventude Negra | C17: =SUBTOTAL(109,C18:C20) -> 15508044 | D17: =SUBTOTAL(109,D18:D20) -> 14471894 | E17: =SUBTOTAL(109,E18:E20) -> 10471894 | F17: =SUBTOTAL(109,F18:F20) -> 4087916 | G17: =SUBTOTAL(109,G18:G20) -> 0 | H17: =SUBTOTAL(109,H18:H20) -> 6383978 | I17: =SUBTOTAL(109,I18:I20) -> 6373977.5 | J17: =SUBTOTAL(109,J18:J20) -> 3271150 | ... O17: =SUBTOTAL(109,O18:O20) -> 3112828 | P17: =I17/H17 -> 0.9984335 | Q17: =L17/H17 -> 0.51239995 | R17: =M17/H17 -> 0.27743928 | S17: =N17/H17 -> 0.27743928
A18: 0000 - Fortalecimento de Políticas em prol da Vida e do Bem Viver da Juventude Negra - Despesas Diversas | B18: Despesas correntes | C18: 1500000 | D18: 1403142 | E18: 480000 | F18: 0 | H18: =E18-G18-F18 -> 480000 | I18: =SUMIFS(INDIRECT($U18 & W$8),INDIRECT($U18 & "B3:B200"),$V18,INDIRECT($U18 & "D3:D200"),$B18) -> 480000 | J18: 480000 | K18: =J18-L18 -> 0 | L18: =SUMIFS(INDIRECT($U18 & X$8),INDIRECT($U18 & "B3:B200"),$V18,INDIRECT($U18 & "D3:D200"),$B18) -> 480000 | M18: =SUMIFS(INDIRECT($U18 & Y$8),INDIRECT($U18 & "B3:B200"),$V18,INDIRECT($U18 & "D3:D200"),$B18) -> 250016.27 | N18: =SUMIFS(INDIRECT($U18 & Z$8),INDIRECT($U18 & "B3:B200"),$V18,INDIRECT($U18 & "D3:D200"),$B18) -> 250016.27 | O18: =H18-K18-L18 -> 0 | P18: =I18/H18 -> 1 | Q18: =L18/H18 -> 1 | R18: =M18/H18 -> 0.52086723 | S18: =N18/H18 -> 0.52086723 | U18: '21FF - SEPAR'! | V18: =IF(A18="",LEFT(A17,4),LEFT(A18,4)) -> 0000
A19: 0001 - Ações de promoção, proteção e garantia dos direitos da juventude negra | B19: Despesas correntes | C19: 12382044 | D19: 11547747 | E19: 8470744 | F19: 4087916 | H19: =E19-G19-F19 -> 4382828 | I19: =SUMIFS(INDIRECT($U19 & W$8),INDIRECT($U19 & "B3:B200"),$V19,INDIRECT($U19 & "D3:D200"),$B19) -> 4372827.5 | J19: 1270000 | K19: =J19-L19 -> 0 | L19: =SUMIFS(INDIRECT($U19 & X$8),INDIRECT($U19 & "B3:B200"),$V19,INDIRECT($U19 & "D3:D200"),$B19) -> 1270000 | M19: =SUMIFS(INDIRECT($U19 & Y$8),INDIRECT($U19 & "B3:B200"),$V19,INDIRECT($U19 & "D3:D200"),$B19) -> 0 | N19: =SUMIFS(INDIRECT($U19 & Z$8),INDIRECT($U19 & "B3:B200"),$V19,INDIRECT($U19 & "D3:D200"),$B19) -> 0 | O19: =H19-K19-L19 -> 3112828 | P19: =I19/H19 -> 0.99771825 | Q19: =L19/H19 -> 0.28976725 | R19: =M19/H19 -> 0 | S19: =N19/H19 -> 0 | U19: '21FF - SEPAR'! | V19: =IF(A19="",LEFT(A18,4),LEFT(A19,4)) -> 0001
A20: 0002 - Promoção de Justiça Racial e Garantia de Direitos às Pessoas Privadas de Liberdade - ADPF 347 | B20: Despesas correntes | C20: 1626000 | D20: 1521005 | E20: 1521150 | F20: 0 | H20: =E20-G20-F20 -> 1521150 | I20: =SUMIFS(INDIRECT($U20 & W$8),INDIRECT($U20 & "B3:B200"),$V20,INDIRECT($U20 & "D3:D200"),$B20) -> 1521150 | J20: 1521150 | K20: =J20-L20 -> 0 | L20: =SUMIFS(INDIRECT($U20 & X$8),INDIRECT($U20 & "B3:B200"),$V20,INDIRECT($U20 & "D3:D200"),$B20) -> 1521150 | M20: =SUMIFS(INDIRECT($U20 & Y$8),INDIRECT($U20 & "B3:B200"),$V20,INDIRECT($U20 & "D3:D200"),$B20) -> 1521150 | N20: =SUMIFS(INDIRECT($U20 & Z$8),INDIRECT($U20 & "B3:B200"),$V20,INDIRECT($U20 & "D3:D200"),$B20) -> 1521150 | O20: =H20-K20-L20 -> 0 | P20: =I20/H20 -> 1 | Q20: =L20/H20 -> 1 | R20: =M20/H20 -> 1 | S20: =N20/H20 -> 1 | U20: '21FF - SEPAR'! | V20: =IF(A20="",LEFT(A19,4),LEFT(A20,4)) -> 0002
A21: OUVIDORIA | C21: =SUBTOTAL(109,C22:C24) -> 1000000 | D21: =SUBTOTAL(109,D22:D24) -> 926737 | E21: =SUBTOTAL(109,E22:E24) -> 926737 | F21: =SUBTOTAL(109,F22:F24) -> 643937 | G21: =SUBTOTAL(109,G22:G24) -> 0 | H21: =SUBTOTAL(109,H22:H24) -> 282800 | I21: =SUBTOTAL(109,I22:I24) -> 0 | J21: =SUBTOTAL(109,J22:J24) -> 0 | ... O21: =SUBTOTAL(109,O22:O24) -> 282800 | P21: =I21/H21 -> 0 | Q21: =L21/H21 -> 0 | R21: =M21/H21 -> 0 | S21: =N21/H21 -> 0
A22: 21HN - Gestão de Políticas de Ações Afirmativas e de Combate e Superação do Racismo | C22: =SUBTOTAL(109,C24) -> 1000000 | D22: =SUBTOTAL(109,D24) -> 926737 | E22: =SUBTOTAL(109,E24) -> 926737 | F22: =SUBTOTAL(109,F24) -> 643937 | G22: =SUBTOTAL(109,G24) -> 0 | H22: =SUBTOTAL(109,H24) -> 282800 | I22: =SUBTOTAL(109,I24) -> 0 | J22: =SUBTOTAL(109,J24) -> 0 | ... O22: =SUBTOTAL(109,O24) -> 282800 | P22: =I22/H22 -> 0 | Q22: =L22/H22 -> 0 | R22: =M22/H22 -> 0 | S22: =N22/H22 -> 0
A24: 0003 - Ferramentas Nacionais de Recebimento e Encaminhamento de Denúncias de Racismo | B24: Despesas correntes | C24: 1000000 | D24: 926737 | E24: 926737 | F24: 643937 | H24: =E24-G24-F24 -> 282800 | I24: =SUMIFS(INDIRECT($U24 & W$8),INDIRECT($U24 & "B3:B200"),$V24,INDIRECT($U24 & "D3:D200"),$B24) -> 0 | K24: =J24-L24 -> 0 | L24: =SUMIFS(INDIRECT($U24 & X$8),INDIRECT($U24 & "B3:B200"),$V24,INDIRECT($U24 & "D3:D200"),$B24) -> 0 | M24: =SUMIFS(INDIRECT($U24 & Y$8),INDIRECT($U24 & "B3:B200"),$V24,INDIRECT($U24 & "D3:D200"),$B24) -> 0 | N24: =SUMIFS(INDIRECT($U24 & Z$8),INDIRECT($U24 & "B3:B200"),$V24,INDIRECT($U24 & "D3:D200"),$B24) -> 0 | O24: =H24-K24-L24 -> 282800 | P24: =I24/H24 -> 0 | Q24: =L24/H24 -> 0 | R24: =M24/H24 -> 0 | S24: =N24/H24 -> 0 | U24: '21HN - OUV'! | V24: =IF(A24="",LEFT(A22,4),LEFT(A24,4)) -> 0003 | AA24: =H24-I24 -> 282800
A25: SENAPIR | C25: =SUBTOTAL(109,C26:C30) -> 32058194 | D25: =SUBTOTAL(109,D26:D31) -> 39135894 | E25: =SUBTOTAL(109,E26:E31) -> 38735894 | F25: =SUBTOTAL(109,F26:F31) -> 12501549 | G25: =SUBTOTAL(109,G26:G31) -> 0 | H25: =SUBTOTAL(109,H26:H31) -> 26234345 | I25: =SUBTOTAL(109,I26:I31) -> 26285894 | J25: =SUBTOTAL(109,J26:J31) -> 17934709 | K25: =SUBTOTAL(109,K26:K31) -> 291002.06 | ... O25: =SUBTOTAL(109,O26:O31) -> 8299636.2 | P25: =I25/H25 -> 1.0019649 | Q25: =L25/H25 -> 0.6725423 | R25: =M25/H25 -> 0.51904197 | S25: =N25/H25 -> 0.46014567
A26: 21FC - Monitoramento, aperfeiçoamento, articulação e estruturação de políticas de promoção da igualdade racial no âmbito do SINAPIR | C26: =SUBTOTAL(109,C27:C30) -> 32058194 | D26: =SUBTOTAL(109,D27:D31) -> 39135894 | E26: =SUBTOTAL(109,E27:E31) -> 38735894 | F26: =SUBTOTAL(109,F27:F31) -> 12501549 | G26: =SUBTOTAL(109,G27:G31) -> 0 | H26: =SUBTOTAL(109,H27:H31) -> 26234345 | I26: =SUBTOTAL(109,I27:I31) -> 26285894 | J26: =SUBTOTAL(109,J27:J31) -> 17934709 | K26: =SUBTOTAL(109,K27:K31) -> 291002.06 | ... O26: =SUBTOTAL(109,O27:O31) -> 8299636.2 | P26: =I26/H26 -> 1.0019649 | Q26: =L26/H26 -> 0.6725423 | R26: =M26/H26 -> 0.51904197 | S26: =N26/H26 -> 0.46014567
A27: 0000 - Monitoramento, aperfeiçoamento, articulação e estruturação de políticas de promoção da igualdade racial no âmbito do SINAPIR - Despesas Diversas | B27: Despesas correntes | C27: 2663706 | D27: 2473982 | E27: 2473982 | F27: 51549 | H27: =E27-G27-F27 -> 2422433 | I27: =SUMIFS(INDIRECT($U27 & W$8),INDIRECT($U27 & "B3:B200"),$V27,INDIRECT($U27 & "D3:D200"),$B27) -> 2473982 | J27: 2188889.6 | K27: =J27-L27 -> 6273.85 | L27: =SUMIFS(INDIRECT($U27 & X$8),INDIRECT($U27 & "B3:B200"),$V27,INDIRECT($U27 & "D3:D200"),$B27) -> 2182615.8 | M27: =SUMIFS(INDIRECT($U27 & Y$8),INDIRECT($U27 & "B3:B200"),$V27,INDIRECT($U27 & "D3:D200"),$B27) -> 1397287.1 | N27: =SUMIFS(INDIRECT($U27 & Z$8),INDIRECT($U27 & "B3:B200"),$V27,INDIRECT($U27 & "D3:D200"),$B27) -> 1397287.1 | O27: =H27-K27-L27 -> 233543.35 | P27: =I27/H27 -> 1.0212798 | Q27: =L27/H27 -> 0.90100151 | R27: =M27/H27 -> 0.57681143 | S27: =N27/H27 -> 0.57681143 | U27: '21FC - SENAPIR'! | V27: =IF(A27="",LEFT(A26,4),LEFT(A27,4)) -> 0000
B28: Investimento | D28: 50000 | E28: 50000 | F28: 50000 | H28: =E28-G28-F28 -> 0 | I28: =SUMIFS(INDIRECT($U28 & W$8),INDIRECT($U28 & "B3:B200"),$V28,INDIRECT($U28 & "D3:D200"),$B28) -> 0 | K28: =J28-L28 -> 0 | L28: =SUMIFS(INDIRECT($U28 & X$8),INDIRECT($U28 & "B3:B200"),$V28,INDIRECT($U28 & "D3:D200"),$B28) -> 0 | M28: =SUMIFS(INDIRECT($U28 & Y$8),INDIRECT($U28 & "B3:B200"),$V28,INDIRECT($U28 & "D3:D200"),$B28) -> 0 | N28: =SUMIFS(INDIRECT($U28 & Z$8),INDIRECT($U28 & "B3:B200"),$V28,INDIRECT($U28 & "D3:D200"),$B28) -> 0 | O28: =H28-K28-L28 -> 0 | P28: =I28/H28 -> #DIV/0! | Q28: =L28/H28 -> #DIV/0! | R28: =M28/H28 -> #DIV/0! | S28: =N28/H28 -> #DIV/0! | U28: '21FC - SENAPIR'! | V28: =IF(A28="",LEFT(A27,4),LEFT(A28,4)) -> 0000
A29: 0001 - Monitoramento, Avaliação e Gestão da informação de Políticas de Promoção da Igualdade Racial | B29: Despesas correntes | C29: 13757644 | D29: 12777740 | E29: 7721555 | F29: 3473651 | H29: =E29-G29-F29 -> 4247904 | I29: =SUMIFS(INDIRECT($U29 & W$8),INDIRECT($U29 & "B3:B200"),$V29,INDIRECT($U29 & "D3:D200"),$B29) -> 4247904 | J29: 3878238.5 | K29: =J29-L29 -> 284728.21 | L29: =SUMIFS(INDIRECT($U29 & X$8),INDIRECT($U29 & "B3:B200"),$V29,INDIRECT($U29 & "D3:D200"),$B29) -> 3593510.3 | M29: =SUMIFS(INDIRECT($U29 & Y$8),INDIRECT($U29 & "B3:B200"),$V29,INDIRECT($U29 & "D3:D200"),$B29) -> 2023833.2 | N29: =SUMIFS(INDIRECT($U29 & Z$8),INDIRECT($U29 & "B3:B200"),$V29,INDIRECT($U29 & "D3:D200"),$B29) -> 2020333.2 | O29: =H29-K29-L29 -> 369665.47 | P29: =I29/H29 -> 1 | Q29: =L29/H29 -> 0.84594904 | R29: =M29/H29 -> 0.476431 | S29: =N29/H29 -> 0.47560707 | U29: '21FC - SENAPIR'! | V29: =IF(A29="",LEFT(A28,4),LEFT(A29,4)) -> 0001
A30: 0002 - Aperfeiçoamento, estruturação e promoção do SINAPIR - Sistema Nacional de Promoção da Igualdade Racial | B30: Despesas correntes | C30: 15636844 | D30: 14507823 | E30: 19564008 | H30: =E30-G30-F30 -> 19564008 | I30: =SUMIFS(INDIRECT($U30 & W$8),INDIRECT($U30 & "B3:B200"),$V30,INDIRECT($U30 & "D3:D200"),$B30) -> 19564008 | J30: 11867581 | K30: =J30-L30 -> 0 | L30: =SUMIFS(INDIRECT($U30 & X$8),INDIRECT($U30 & "B3:B200"),$V30,INDIRECT($U30 & "D3:D200"),$B30) -> 11867581 | M30: =SUMIFS(INDIRECT($U30 & Y$8),INDIRECT($U30 & "B3:B200"),$V30,INDIRECT($U30 & "D3:D200"),$B30) -> 10195606 | N30: =SUMIFS(INDIRECT($U30 & Z$8),INDIRECT($U30 & "B3:B200"),$V30,INDIRECT($U30 & "D3:D200"),$B30) -> 8654000 | O30: =H30-K30-L30 -> 7696427.3 | P30: =I30/H30 -> 1 | Q30: =L30/H30 -> 0.60660273 | R30: =M30/H30 -> 0.52114096 | S30: =N30/H30 -> 0.4423429 | U30: '21FC - SENAPIR'! | V30: =IF(A30="",LEFT(A29,4),LEFT(A30,4)) -> 0002
B31: Investimento | C31: 10000000 | D31: 9326349 | E31: 8926349 | F31: 8926349 | H31: =E31-G31-F31 -> 0 | I31: =SUMIFS(INDIRECT($U31 & W$8),INDIRECT($U31 & "B3:B200"),$V31,INDIRECT($U31 & "D3:D200"),$B31) -> 0 | L31: =SUMIFS(INDIRECT($U31 & X$8),INDIRECT($U31 & "B3:B200"),$V31,INDIRECT($U31 & "D3:D200"),$B31) -> 0 | M31: =SUMIFS(INDIRECT($U31 & Y$8),INDIRECT($U31 & "B3:B200"),$V31,INDIRECT($U31 & "D3:D200"),$B31) -> 0 | N31: =SUMIFS(INDIRECT($U31 & Z$8),INDIRECT($U31 & "B3:B200"),$V31,INDIRECT($U31 & "D3:D200"),$B31) -> 0 | O31: =H31-K31-L31 -> 0 | P31: =I31/H31 -> #DIV/0! | Q31: =L31/H31 -> #DIV/0! | R31: =M31/H31 -> #DIV/0! | S31: =N31/H31 -> #DIV/0! | U31: '21FC - SENAPIR'! | V31: =IF(A31="",LEFT(A30,4),LEFT(A31,4)) -> 0002
A32: SQPT | C32: =SUBTOTAL(109,C33:C40) -> 42135688 | D32: =SUBTOTAL(109,D33:D40) -> 39148741 | E32: =SUBTOTAL(109,E33:E40) -> 39212823 | F32: =SUBTOTAL(109,F33:F40) -> 8084934 | G32: =SUBTOTAL(109,G33:G40) -> 0 | H32: =SUBTOTAL(109,H33:H40) -> 31127889 | I32: =SUBTOTAL(109,I33:I40) -> 30832395 | J32: =SUBTOTAL(109,J33:J40) -> 22682540 | ... O32: =SUBTOTAL(109,O33:O40) -> 8445349 | P32: =I32/H32 -> 0.9905071 | Q32: =L32/H32 -> 0.72587447 | R32: =M32/H32 -> 0.63172393 | S32: =N32/H32 -> 0.56101113
A33: 21FE - Apoio à Implementação de Políticas para Quilombolas, Comunidades Tradicionais de Matriz Africana, Povos de Terreiro e Ciganos | C33: =SUBTOTAL(109,C34:C40) -> 42135688 | D33: =SUBTOTAL(109,D34:D40) -> 39148741 | E33: =SUBTOTAL(109,E34:E40) -> 39212823 | F33: =SUBTOTAL(109,F34:F40) -> 8084934 | G33: =SUBTOTAL(109,G34:G40) -> 0 | H33: =SUBTOTAL(109,H34:H40) -> 31127889 | I33: =SUBTOTAL(109,I34:I40) -> 30832395 | J33: =SUBTOTAL(109,J34:J40) -> 22682540 | ... O33: =SUBTOTAL(109,O34:O40) -> 8445349 | P33: =I33/H33 -> 0.9905071 | Q33: =L33/H33 -> 0.72587447 | R33: =M33/H33 -> 0.63172393 | S33: =N33/H33 -> 0.56101113
A34: 0000 - Apoio à Implementação de Políticas para Quilombolas, Comunidades Tradicionais de Matriz Africana, Povos de Terreiro e Ciganos - Despesas Diversas | B34: Despesas correntes | C34: 2000000 | D34: 1859799 | E34: 2499130 | F34: 0 | H34: =E34-G34-F34 -> 2499130 | I34: =SUMIFS(INDIRECT($U34 & W$8),INDIRECT($U34 & "B3:B200"),$V34,INDIRECT($U34 & "D3:D200"),$B34) -> 2499130 | J34: 1805034.4 | K34: =J34-L34 -> 0 | L34: =SUMIFS(INDIRECT($U34 & X$8),INDIRECT($U34 & "B3:B200"),$V34,INDIRECT($U34 & "D3:D200"),$B34) -> 1805034.4 | M34: =SUMIFS(INDIRECT($U34 & Y$8),INDIRECT($U34 & "B3:B200"),$V34,INDIRECT($U34 & "D3:D200"),$B34) -> 1327574.9 | N34: =SUMIFS(INDIRECT($U34 & Z$8),INDIRECT($U34 & "B3:B200"),$V34,INDIRECT($U34 & "D3:D200"),$B34) -> 1327574.9 | O34: =H34-K34-L34 -> 694095.65 | P34: =I34/H34 -> 1 | Q34: =L34/H34 -> 0.72226509 | R34: =M34/H34 -> 0.53121484 | S34: =N34/H34 -> 0.53121484 | U34: '21FE - SQPT'! | V34: 0000
A35: 0001 - Promoção, proteção e garantia dos direitos dos povos Ciganos | B35: Despesas correntes | C35: 7463631 | D35: 6934100 | E35: 7171507 | F35: 182065 | H35: =E35-G35-F35 -> 6989442 | I35: =SUMIFS(INDIRECT($U35 & W$8),INDIRECT($U35 & "B3:B200"),$V35,INDIRECT($U35 & "D3:D200"),$B35) -> 6986541.2 | J35: 6903894 | K35: =J35-L35 -> 12600 | L35: =SUMIFS(INDIRECT($U35 & X$8),INDIRECT($U35 & "B3:B200"),$V35,INDIRECT($U35 & "D3:D200"),$B35) -> 6891294 | M35: =SUMIFS(INDIRECT($U35 & Y$8),INDIRECT($U35 & "B3:B200"),$V35,INDIRECT($U35 & "D3:D200"),$B35) -> 6264858 | N35: =SUMIFS(INDIRECT($U35 & Z$8),INDIRECT($U35 & "B3:B200"),$V35,INDIRECT($U35 & "D3:D200"),$B35) -> 5454858 | O35: =H35-K35-L35 -> 85547.99 | P35: =I35/H35 -> 0.99958497 | Q35: =L35/H35 -> 0.98595768 | R35: =M35/H35 -> 0.89633164 | S35: =N35/H35 -> 0.78044256 | U35: '21FE - SQPT'! | V35: 0001
B36: Investimento | C36: 1000000 | D36: 926738 | E36: 500000 | F36: 500000 | H36: =E36-G36-F36 -> 0 | I36: =SUMIFS(INDIRECT($U36 & W$8),INDIRECT($U36 & "B3:B200"),$V36,INDIRECT($U36 & "D3:D200"),$B36) -> 0 | K36: =J36-L36 -> 0 | L36: =SUMIFS(INDIRECT($U36 & X$8),INDIRECT($U36 & "B3:B200"),$V36,INDIRECT($U36 & "D3:D200"),$B36) -> 0 | M36: =SUMIFS(INDIRECT($U36 & Y$8),INDIRECT($U36 & "B3:B200"),$V36,INDIRECT($U36 & "D3:D200"),$B36) -> 0 | N36: =SUMIFS(INDIRECT($U36 & Z$8),INDIRECT($U36 & "B3:B200"),$V36,INDIRECT($U36 & "D3:D200"),$B36) -> 0 | O36: =H36-K36-L36 -> 0 | P36: =I36/H36 -> #DIV/0! | Q36: =L36/H36 -> #DIV/0! | R36: =M36/H36 -> #DIV/0! | S36: =N36/H36 -> #DIV/0! | U36: '21FE - SQPT'! | V36: 0001
A37: 0002 - Promoção, proteção e garantia dos direitos das Comunidades Tradicionais de Matriz Africana e Povos de Terreiro | B37: Despesas correntes | C37: 9649828 | D37: 8973364 | E37: 9103035 | F37: 2521718 | H37: =E37-G37-F37 -> 6581317 | I37: =SUMIFS(INDIRECT($U37 & W$8),INDIRECT($U37 & "B3:B200"),$V37,INDIRECT($U37 & "D3:D200"),$B37) -> 6581308.2 | J37: 5559022 | K37: =J37-L37 -> 0 | L37: =SUMIFS(INDIRECT($U37 & X$8),INDIRECT($U37 & "B3:B200"),$V37,INDIRECT($U37 & "D3:D200"),$B37) -> 5559022 | M37: =SUMIFS(INDIRECT($U37 & Y$8),INDIRECT($U37 & "B3:B200"),$V37,INDIRECT($U37 & "D3:D200"),$B37) -> 4096567.2 | N37: =SUMIFS(INDIRECT($U37 & Z$8),INDIRECT($U37 & "B3:B200"),$V37,INDIRECT($U37 & "D3:D200"),$B37) -> 4092927.1 | O37: =H37-K37-L37 -> 1022295 | P37: =I37/H37 -> 0.99999866 | Q37: =L37/H37 -> 0.84466711 | R37: =M37/H37 -> 0.62245402 | S37: =N37/H37 -> 0.62190092 | U37: '21FE - SQPT'! | V37: 0002
B38: Investimento | C38: 2500000 | D38: 2316845 | E38: 1937174 | F38: 1158587 | H38: =E38-G38-F38 -> 778587 | I38: =SUMIFS(INDIRECT($U38 & W$8),INDIRECT($U38 & "B3:B200"),$V38,INDIRECT($U38 & "D3:D200"),$B38) -> 778587 | K38: =J38-L38 -> 0 | L38: =SUMIFS(INDIRECT($U38 & X$8),INDIRECT($U38 & "B3:B200"),$V38,INDIRECT($U38 & "D3:D200"),$B38) -> 0 | M38: =SUMIFS(INDIRECT($U38 & Y$8),INDIRECT($U38 & "B3:B200"),$V38,INDIRECT($U38 & "D3:D200"),$B38) -> 0 | N38: =SUMIFS(INDIRECT($U38 & Z$8),INDIRECT($U38 & "B3:B200"),$V38,INDIRECT($U38 & "D3:D200"),$B38) -> 0 | O38: =H38-K38-L38 -> 778587 | P38: =I38/H38 -> 1 | Q38: =L38/H38 -> 0 | R38: =M38/H38 -> 0 | S38: =N38/H38 -> 0 | U38: '21FE - SQPT'! | V38: 0002
A39: 0003 - Promoção, proteção e garantia dos direitos das populações e comunidades Quilombolas | B39: Despesas correntes | C39: 16522229 | D39: 15357681 | E39: 15221763 | F39: 942350 | H39: =E39-G39-F39 -> 14279413 | I39: =SUMIFS(INDIRECT($U39 & W$8),INDIRECT($U39 & "B3:B200"),$V39,INDIRECT($U39 & "D3:D200"),$B39) -> 13986829 | J39: 8414589.7 | K39: =J39-L39 -> 75000.13 | L39: =SUMIFS(INDIRECT($U39 & X$8),INDIRECT($U39 & "B3:B200"),$V39,INDIRECT($U39 & "D3:D200"),$B39) -> 8339589.5 | M39: =SUMIFS(INDIRECT($U39 & Y$8),INDIRECT($U39 & "B3:B200"),$V39,INDIRECT($U39 & "D3:D200"),$B39) -> 7975232.2 | N39: =SUMIFS(INDIRECT($U39 & Z$8),INDIRECT($U39 & "B3:B200"),$V39,INDIRECT($U39 & "D3:D200"),$B39) -> 6587732.2 | O39: =H39-K39-L39 -> 5864823.3 | P39: =I39/H39 -> 0.97951006 | Q39: =L39/H39 -> 0.58402888 | R39: =M39/H39 -> 0.55851261 | S39: =N39/H39 -> 0.46134475 | U39: '21FE - SQPT'! | V39: 0003
B40: Investimento | C40: 3000000 | D40: 2780214 | E40: 2780214 | F40: 2780214 | H40: =E40-G40-F40 -> 0 | I40: =SUMIFS(INDIRECT($U40 & W$8),INDIRECT($U40 & "B3:B200"),$V40,INDIRECT($U40 & "D3:D200"),$B40) -> 0 | K40: =J40-L40 -> 0 | L40: =SUMIFS(INDIRECT($U40 & X$8),INDIRECT($U40 & "B3:B200"),$V40,INDIRECT($U40 & "D3:D200"),$B40) -> 0 | M40: =SUMIFS(INDIRECT($U40 & Y$8),INDIRECT($U40 & "B3:B200"),$V40,INDIRECT($U40 & "D3:D200"),$B40) -> 0 | N40: =SUMIFS(INDIRECT($U40 & Z$8),INDIRECT($U40 & "B3:B200"),$V40,INDIRECT($U40 & "D3:D200"),$B40) -> 0 | O40: =H40-K40-L40 -> 0 | P40: =I40/H40 -> #DIV/0! | Q40: =L40/H40 -> #DIV/0! | R40: =M40/H40 -> #DIV/0! | S40: =N40/H40 -> #DIV/0! | U40: '21FE - SQPT'! | V40: 0003
A41: CNPIR | C41: =SUBTOTAL(109,C42:C43) -> 2000000 | D41: =SUBTOTAL(109,D42:D43) -> 1853476 | E41: =SUBTOTAL(109,E42:E43) -> 2253476 | F41: =SUBTOTAL(109,F42:F43) -> 0 | G41: =SUBTOTAL(109,G42:G43) -> 0 | H41: =SUBTOTAL(109,H42:H43) -> 2253476 | I41: =SUBTOTAL(109,I42:I43) -> 1853476 | J41: =SUBTOTAL(109,J42:J43) -> 1479048.9 | ... O41: =SUBTOTAL(109,O42:O43) -> 774427.12 | P41: =I41/H41 -> 0.82249645 | Q41: =L41/H41 -> 0.61640278 | R41: =M41/H41 -> 0.52058798 | S41: =N41/H41 -> 0.52058798
A42: 21FG - Apoio no Funcionamento do Conselho Nacional de Promoção da Igualdade Racial - CNPIR | C42: =SUBTOTAL(109,C43:C43) -> 2000000 | D42: =SUBTOTAL(109,D43:D43) -> 1853476 | E42: =SUBTOTAL(109,E43:E43) -> 2253476 | F42: =SUBTOTAL(109,F43:F43) -> 0 | G42: =SUBTOTAL(109,G43:G43) -> 0 | H42: =SUBTOTAL(109,H43:H43) -> 2253476 | I42: =SUBTOTAL(109,I43:I43) -> 1853476 | J42: =SUBTOTAL(109,J43:J43) -> 1479048.9 | ... O42: =SUBTOTAL(109,O43:O43) -> 774427.12 | P42: =I42/H42 -> 0.82249645 | Q42: =L42/H42 -> 0.61640278 | R42: =M42/H42 -> 0.52058798 | S42: =N42/H42 -> 0.52058798
A43: 0000 - Apoio no Funcionamento do Conselho Nacional de Promoção da Igualdade Racial - Despesas Diversas | B43: Despesas correntes | C43: 2000000 | D43: 1853476 | E43: 2253476 | H43: =E43-G43-F43 -> 2253476 | I43: =SUMIFS(INDIRECT($U43 & W$8),INDIRECT($U43 & "B3:B200"),$V43,INDIRECT($U43 & "D3:D200"),$B43) -> 1853476 | J43: 1479048.9 | K43: =J43-L43 -> 90000 | L43: =SUMIFS(INDIRECT($U43 & X$8),INDIRECT($U43 & "B3:B200"),$V43,INDIRECT($U43 & "D3:D200"),$B43) -> 1389048.9 | M43: =SUMIFS(INDIRECT($U43 & Y$8),INDIRECT($U43 & "B3:B200"),$V43,INDIRECT($U43 & "D3:D200"),$B43) -> 1173132.5 | N43: =SUMIFS(INDIRECT($U43 & Z$8),INDIRECT($U43 & "B3:B200"),$V43,INDIRECT($U43 & "D3:D200"),$B43) -> 1173132.5 | O43: =H43-K43-L43 -> 774427.12 | P43: =I43/H43 -> 0.82249645 | Q43: =L43/H43 -> 0.61640278 | R43: =M43/H43 -> 0.52058798 | S43: =N43/H43 -> 0.52058798 | U43: '21FG - CNPIR'! | V43: 0000
A44: SECRETARIA EXECUTIVA | C44: =SUBTOTAL(109,C45:C58) -> 41465065 | D44: =SUBTOTAL(109,D45:D58) -> 38497208 | E44: =SUBTOTAL(109,E45:E58) -> 38497208 | F44: =SUBTOTAL(109,F45:F58) -> 985707 | G44: =SUBTOTAL(109,G45:G58) -> 0 | H44: =SUBTOTAL(109,H45:H58) -> 37511501 | I44: =SUBTOTAL(109,I45:I58) -> 39991802 | J44: =SUBTOTAL(109,J45:J58) -> 35736318 | ... O44: =SUBTOTAL(109,O45:O58) -> 1775183.1 | P44: =I44/H44 -> 1.0661211 | Q44: =L44/H44 -> 0.92840726 | R44: =M44/H44 -> 0.58989047 | S44: =N44/H44 -> 0.57901404
...

Sheet 2000 - SE
A1: ACOMPANHAMENTO EXECUÇÃO FINALÍSTICAS - 2025
A2: UNIDADE | B2: PO | C2: ANO DE FORMALIZAÇÃO | D2: GRUPO DE DESPESA | E2: INICIATIVAS | F2: SEI | G2: DIRETORIA | H2: RESPONSÁVEL PELA FORMALIZAÇÃO | I2: INSTRUMENTO | J2: SIAFI | K2: PARCEIRO | L2: PROGRAMADO 2026 | M2: EMPENHADO 2026 | N2: LIQUIDADO 2026 | O2: PAGO 2026 | P2: STATUS | Q2: OBSERVAÇÃO (PENDÊNCIAS)
A3: SECRETARIA EXECUTIVA | B3: 0000 | C3: 2025 | D3: Despesas Correntes | E3: Administração da Unidade - Despesas Diversas | F3: Vários | G3: DGA | H3: Jeremias | I3: Contrato | J3: não há | K3: Vários | L3: 30065065 | M3: 30695767 | N3: 19889117 | O3: 19481126
B4: 0000 | D4: Investimento | E4: Administração da Unidade - Despesas Diversas | F4: Vários | G4: DGA | H4: Jeremias | I4: Contrato | J4: não há | K4: Vários | L4: 1000000 | M4: 168239 | N4: 160319 | O4: 160319
B5: 0007 | D5: Despesas Correntes | E5: 0007 - Capacitação de Servidores Públicos Federais em Processo de Qualificação e Requalificação | F5: Vários | G5: DGA | H5: Jeremias | I5: Contrato | J5: não há | K5: Vários | L5: 526737 | M5: 466789.99 | N5: 338040.49 | O5: 338040.49
B6: 000B | D6: Despesas Correntes | E6: 000B - Ajuda de custo (mobilização e desmobilização) | F6: Vários | G6: DGA | H6: Jeremias | I6: Contrato | J6: não há | K6: Vários | L6: 1500000 | M6: 371386.4 | N6: 349478.89 | O6: 349478.89
B7: 000C | D7: Despesas Correntes | E7: 000C - Ajuda de custo para Estagiários | F7: Vários | G7: DGA | H7: Jeremias | I7: Contrato | J7: não há | K7: Vários | L7: 1000000 | M7: 456000 | N7: 410439.79 | O7: 410439.79
B8: 000F | D8: Despesas Correntes | E8: 000F - Integração e Aquisição de Tecnologia da Informação | F8: Vários | G8: DGA | H8: Jeremias | I8: Contrato | J8: não há | K8: Vários | L8: 1400000 | M8: 450471.58 | N8: 101171.82 | O8: 101171.82
B9: 000F | D9: Investimento | E9: 000F - Integração e Aquisição de Tecnologia da Informação | F9: Vários | G9: DGA | H9: Jeremias | I9: Contrato | J9: não há | K9: Vários | L9: 1000000 | M9: 5547.55
B10: 0010 | D10: Despesas Correntes | E10: 0010 - Conservação de ativos da União | F10: Vários | G10: DGA | H10: Jeremias | I10: Contrato | J10: não há | K10: Vários | L10: 1000000 | M10: 811290.66
B11: 0010 | D11: Investimento | E11: 0010 - Conservação de ativos da União | F11: Vários | G11: DGA | H11: Jeremias | I11: Contrato | J11: não há | K11: Vários | L11: 1000000 | M11: 10349.97 | N11: 4199.99 | O11: 4199.99
G13: TOTAL | L13: =SUM(L3:L12) -> 38491802 | M13: =SUM(M3:M12) -> 33435842 | N13: =SUM(N3:N12) -> 21252767 | O13: =SUM(O3:O12) -> 20844776
G14: Dotação livre para empenho | L14: ='Consolidado 2026'!H45 -> 36121393
G15: (%) PLE/PROGRAMADO | L15: =L13/L14 -> 1.0656234
P17: 267237.57

Sheet 216H - SE
A2: ACOMPANHAMENTO EXECUÇÃO GESTÃO - 2025
A3: UNIDADE | B3: PO | C3: ANO DE FORMALIZAÇÃO | D3: GRUPO DE DESPESA | E3: INICIATIVAS | F3: SEI | G3: DIRETORIA | H3: RESPONSÁVEL PELA FORMALIZAÇÃO | I3: INSTRUMENTO | J3: SIAFI | K3: PARCEIRO | L3: PROGRAMADO 2026 | M3: EMPENHADO 2026 | N3: LIQUIDADO 2026 | O3: PAGO 2026 | P3: STATUS
A4: SECRETARIA EXECUTIVA | B4: 0000 | C4: 2025 | D4: Despesas correntes | E4: não há | F4: Vários | G4: DGA | H4: Jerê / Nayara | I4: Pessoal | J4: não há | K4: não há | L4: 1500000 | M4: 1390108 | N4: 874909.71 | O4: 874909.71 | P4: Empenhado
G8: TOTAL | L8: =SUM(L4:L7) -> 1500000 | M8: =SUM(M4:M7) -> 1390108 | N8: =SUM(N4:N7) -> 874909.71 | O8: =SUM(O4:O7) -> 874909.71
G9: Dotação livre para empenho | L9: ='Consolidado 2026'!H55 -> 1390108
G10: (%) PLE/PROGRAMADO | L10: =L8/L9 -> 1.0790529

Sheet 21FC - SENAPIR
A1: ACOMPANHAMENTO EXECUÇÃO FINALÍSTICAS - 2025
A2: UNIDADE | B2: PO | C2: ANO DE FORMALIZAÇÃO | D2: GRUPO DE DESPESA | E2: INICIATIVAS | F2: SEI | G2: DIRETORIA | H2: RESPONSÁVEL PELA FORMALIZAÇÃO | I2: INSTRUMENTO | J2: SIAFI | K2: PARCEIRO | L2: PROGRAMADO 2026 | M2: EMPENHADO 2026 | N2: LIQUIDADO 2026 | O2: PAGO 2026 | P2: STATUS | Q2: PREVISÃO DE DESCENTRALIZAÇÃO | R2: OBSERVAÇÃO (PENDÊNCIAS) | S2: ENTREGA PPA
A3: SENAPIR | B3: 0000 | C3: 2026 | D3: Despesas correntes | E3: DIARIAS E PASSAGENS /DESPESAS ADMINISTRATIVAS | I3: CONTRATO | L3: 2473982 | M3: 2182615.8 | N3: 1397287.1 | O3: 1397287.1 | Q3: -
B4: 0001 | C4: 2023 | D4: Despesas correntes | E4: Cooperação para realização de pesquisas e desenvolvimento de indicadores e monitoramento de políticas públicas | F4: 21290.200603/2023-66 | G4: DAMGI | H4: Luciano Silva | I4: TED | J4: 945512 | K4: IPEA | L4: 117720 | P4: Empenhado | Q4: - | R4: 19/10/26: Despacho(65118481) Comunicação do fim de vigência; 13/10/26: Ofício(64906505) Prestação de Contas da Descentralização de Crédito - IPEA; 28/09/26: Despacho (64641576)envio do Ofício ao IPEA solcitando RCO; 21/09/26: Despacho (64409549) solicitação RCO; 14/09/26: Despacho(63724637) Comunicação fim da vigência 22/09/26; 17/08/26: Ofício DGA (63658861) Comunicação de fim de vigência do TED; 10/08/26: Nota Técnica(62835977) Análise do RCO. 20/07/26: TED em execução. Conforme cronograma plano de trabalho do TED, 2026NC000088 (57431120)e 2026PF000022 (57732657) emitidas em fevereiro/2026. | S4: 2071 - Observatório de monitoramento e avaliação do SINAPIR
B5: 0001 | C5: 2025 | D5: Despesas correntes | E5: ADITIVO - Plataforma ODS Racial - Monitoramento e inteligência de dados de indicadores da população negra no Brasil | F5: 21290.200789/2023-53 | G5: DAMGI | H5: Leandro/Luciano Silva | I5: TED | J5: 946960 | K5: UFPB | L5: 72000 | M5: 72000 | P5: Empenhado | Q5: junho | R5: 19/10/26: Anexo (65247630) Resposta a Nota Técnica nº 187/2026/MIR; 13/10/26: Despacho (64978265)repasse financeiro no valor de R$ 28.500,00; 05/10/26: Declaração(64901388); 28/09/26: Despacho(64553703)repasse financeiro no valor de R$ 9.000,00;14/09/26: Despacho (63981888) repasse financeiro no valor de R$ 20.000,00; 24/08/26: Despacho (63842878) repasse financeiro no valor de R$ 4.000,00 em 24/08/26; 17/08/26: Despacho (63293462) repasse financeiro no valor de R$ 2.000,00 em 02/08/26; 27/07/26: Ofício Gab (63126977)Celebração de Termo Aditivo de Suplementação, Vigência e Repasse financeiro; 20/07/26: Descentralização Orçamentária (62788574); 06/07/26: Termo Aditivo aguardando assinatura da Ministra(62321007). Autorização prévia celebração de termo aditivo de vigência com suplementação de recursos. 16/06/26: Aguardando a resposta da SE ao Ofício do Gabinete (60546011); 26/05/2026: O Aditivo correspondente a inclusão de uma nova meta objetivando: novas funcionalidades à Plataforma ODS Racial, o ajuste de prazos de entrega e a adequação do cronograma de desembolso. Ofício(60172451) de 10/04/2026 encaminhando a Minuta do Aditivo de Termo de Execução Descentralização - TED (56583856) e Minuta do Plano de Trabalho atualizado (56574438) | S5: 2071 - Observatório de monitoramento e avaliação do SINAPIR
B6: 0001 | C6: 2023 | D6: Despesas correntes | E6: Plataforma ODS Racial - Monitoramento e inteligência de dados de indicadores da população negra no Brasil | F6: 21290.200789/2023-53 | G6: DAMGI | H6: Leandro/Luciano Silva | I6: TED | J6: 946960 | K6: UFPB | L6: =45716.3 -> 45716.3 | M6: 42214.39 | N6: 20003.91 | O6: 16503.91 | P6: Empenhado | Q6: junho | R6: 19/10/26: Anexo (65247630) Resposta a Nota Técnica nº 187/2026/MIR; 13/10/26: Despacho (64978265)repasse financeiro no valor de R$ 28.500,00; 05/10/26: Declaração(64901388); 28/09/26: Despacho(64553703)repasse financeiro no valor de R$ 9.000,00; 14/09/26: Despacho (63981888) repasse financeiro no valor de R$ 20.000,00; 24/08/26: Despacho (63842878) repasse financeiro no valor de R$ 4.000,00 em 24/08/26; 17/08/26: Despacho (63293462) repasse financeiro no valor de R$ 2.000,00 em 02/08/26; 27/07/26: Ofício Gab (63126977)Celebração de Termo Aditivo de Suplementação e Vigência e Repasse financeiro; 20/07/26: Descentralização Orçamentária (62788574); 06/07/26: Termo Aditivo aguardando assinatura da Ministra(62321007). Autorização prévia celebração de termo aditivo de vigência com suplementação de recursos. 16/06/26: Aguardando a resposta da SE ao Ofício do Gabinete (60546011); 26/05/2026: corresponde a novo empenho tendo em vista anulação de empenho/devolução de crédito, conforme e-mail da Instituição à CGMO e à DGA em novembro/2025. Constitui parte do valor do aditivo, o qual totalizará R$ 117.716,30. | S6: 2071 - Observatório de monitoramento e avaliação do SINAPIR
B7: 0001 | C7: 2025 | D7: Despesas correntes | E7: ADITIVO - Apoio a pesquisa e eventos (CNPQ) | F7: 21290.200530/2024-93 | G7: DAMGI | H7: Ana Carolina | I7: TED | J7: 958214 | K7: CNPQ | P7: Instrução Processual | Q7: junho | R7: 19/10/26: Despacho (64864975)repasse financeiro no valor de R$ 98.760,00; 28/09/26: Despacho (63993205) repasse financeiro no valor de R$ 98.760,00; 24/08/26: Despacho(63713250) Reunião de Apresentação dos projetos selecionados pela Chamada CNPq/MIR nº 18/2025; 17/08/26: Despacho (63292965) repasse financeiro no valor de R$ 107.660,00; 27/07/26: Despacho (62715339)repasse financeiro no valor de R$ 109.310,00; 20/07/26: Aguardando a resposta da solicitação do RCO (61672471). Por sugestão do CNPQ, será desmembrado em a) 1 aditivo de 223 mil, para recurso de custeio e apoio a projetos remanescentes e 2) novo TED, com recurso contrapartida Edital Lelia Gonzalez. Reunião agendada para 08 de junho para revisão no Plano de trabalho. 26/05/2026: O TED está em execução. O recurso programado corresponde a um aditivo. Objetiva a realização de uma nova chamada pública de projetos de pesquisa voltados à temática racial, bem como a suplementação da chamada realizada em 2025. Manifestação de interesse enviada (SEI 56210415). Aguardando Plano de Trabalho. | S7: 2071 - Observatório de monitoramento e avaliação do SINAPIR
B8: 0001 | C8: 2025 | D8: Despesas correntes | E8: Apoio a pesquisas - Edital Lélia Gonzalez | F8: 21290.002101/2026-14 | G8: DAMGI | H8: Ana Carolina | I8: TED | K8: CNPQ | P8: Instrução Processual | Q8: junho | R8: 19/10/26: Ofício(64959423) Diligências; 05/10/26: TED 22(64490576) a ser assinado; 14/09/26: Nota Informativa (64101324) Ajuste no Cronograma de Desembolso; 31/08/26: Despacho DGA(63942470) autorização prévia; 24/08/26: Despacho DGA (63847784) com análise da documentação verificou-se que o processo encontra-se regularmente instruído;17/08/26: Nota Informativa DAMGI(63670143) a ser assinada; 05/08/26: Ofício(63315344)à SE e DGA. Encaminhamento de proposta de TED entre o MIR e CNPq; 03/08/26: Despacho DAMGI(62970623)para celebração do TED; 06/07/26: Resposta do CNPQ a manifestação de interesse, Ofício (62599686); 29/06/26: Redução do valor programado de R$ 2mi para R$ 1,5mi. 22/06/26: Despacho DAMGI(62204132) manifestação de interesse. Novo TED - Apoio a Pesquisas e Edital Lelia Gonzalez 1.500.000,00
B9: 0001 | C9: 2025 | D9: Despesas correntes | E9: INCLUA - Igualdade Racial | F9: 21290.001303/2025-68 | G9: DAMGI | H9: Ana Carolina | I9: TED | J9: 978843 | K9: IPEA | L9: 532400 | M9: 532400 | N9: 16080.49 | O9: 16080.49 | P9: Empenhado | Q9: - | R9: 19/10/26: Despacho(64953810) Encaminhamento da relação de municípios selecionados para participação no assessoramento relacionado à Plataforma Inclua Igualdade Racial; 05/10/26: Ofício SE(64846317) a ser assinado;28/09/26: Despacho(64680976) Encaminhamento da relação de municípios selecionados para participação no assessoramento Inclua; 21/09/26: Nota Técnica (63871862)Análise parcial RCO; 24/08/26: Despacho (62951307) encaminhando os ofícios ao IPEA; 17/08/26: Ofício 12502 (62948671) encaminhado ao IPEA em 17/07/26; 13/07/26: Despacho suspensão IA. Defeso Eleitoral(62825185);06/07/26: TED em execução. Conforme cronograma plano de trabalho do TED, Nota de Crédito - 2026NC000010 (57303054) emitida em janeiro/2026. 2026PF000023 (57737226) em fevereiro de 2026. | S9: 2071 - Observatório de monitoramento e avaliação do SINAPIR
B10: 0001 | C10: 2024 | D10: Despesas correntes | E10: UFSB - Observatório ODS 18 | F10: 21290.201857/2024-82 | G10: DAMGI | H10: Emanuel/Luciano Silva | I10: TED | J10: 966020 | K10: UFSB | L10: 536699.31 | M10: 536699.31 | N10: 536699.31 | O10: 536699.31 | P10: Pago/Liquidado | Q10: junho | R10: 19/10/26: Despacho (62690910) Repasse financeiro no valor de R$ 901.699,31 em 08/07/26; 13/07/26: Valor liquidado R$ 536.699,31; 06/07/26: valor empenhado R$ 536.699,31; 26/05/2026: Programado para abril/2026. Conforme cronograma plano de trabalho do TED, 2026NC0000075, SEI-57260689 emitida em janeiro/2026. Estorno da 2026NC0000075(SEI-57265246) em janeiro/2026. Parcel | S10: 2071 - Observatório de monitoramento e avaliação do SINAPIR
B11: 0001 | C11: 2025 | D11: Despesas correntes | E11: TED - UFSB - Estratrégias de Territorialização do ODS18 (continuidade das ações do Observatório do ODS 18), voltadas para entes subnacionais e OSC | F11: 21290.004241/2025-46 | G11: DAMGI | H11: Luciano Silva | I11: TED | K11: UFSB | L11: 223435 | P11: Instrução Processual | Q11: julho | R11: 19/10/26: Ofício Gab SENAPIR (64927041)a ser assinado; 05/10/26: Despacho (64600062)encaminhando TED; 21/09/26: Despacho SE(64129045) a ser assinado; 31/08/26: Despacho DGA(63792446)processo encontra-se regularmente instruído; 24/08/26: Despacho DGA (63769592)Resposta da solicitação de cumprimento da Portaria GAB/MIR nº 394; 17/08/26: Despacho DAMGI (63663029) Cumprimento da Portaria GAB/MIR nº 394, 15/07/26; 10/08/26: Portaria(63449564) fluxo de instrução, análise e tramitação dos processos administrativos;03/08/26: Ofício (62982241)à SE para celebração do TED; 20/07/26: Despacho DAMGI (62956804) ao Gabinete; 13/07/26:Aguardando assinatura do Secretário para SE(Ofício 62124772);11/06/26:Encaminhado Despacho 62036120 ao Gab SENAPIR com justes realizados em virtude das recomendações solicitadas pela Secretaria-Executiva; 28/05 - em ajuste, cf recomendações SE MIR. 26/05/2026 Aguardando apreciação SE/MIR - Ofício SENAPIR enviado em 20/5 SEI 57777491; 06/04/2026:(Despacho 59510990, de 28/01/26 - Instrução concluída na Diretoria). Instrução revisada na Diretoria, conforme NT 57611365, alterando o cronograma de desembolso para 2026 (R$ 1 milhão para 2026). Despacho 59510990, de 27/03/26, para Gabinete SENAPIR | S11: 2071 - Observatório de monitoramento e avaliação do SINAPIR
B12: 0001 | C12: 2026 | D12: Despesas correntes | E12: FIAR - ENAP Oferta de cursos síncronos e novo curso | F12: 21290.002743/2026-13 | G12: DAMGI | H12: Ana Carolina | I12: TEDinho | K12: ENAP | L12: 85000 | P12: Instrução Processual | Q12: - | R12: 19/10/26: Ofício(64959975) Proposta de parceria para curso sobre orçamento sensível a raça; 05/10/26: Despacho (64465148) Comunica o envio do Ofício Enap; 14/09/26: Ofício(64362344) Manifestação de Interesse; 08/09/26: Despacho DAMGI(62834700) encaminhando Minuta de Ofício (Manifestação de interesse) em 16/07/26; 20/07/26: CGAGC instrurá novo processo com Manifestação de interesse para Curso Síncrono - Orçamento sensivel a raça - verificar processo com Ana Carolina 13/07/26: Não ocorrerá em 2026; 22/12/2025: Ações do FIAR, para programação junto à ENAP Verificar com a Carol | S12: 0400 - Formação de gestores públicos para promoção da igualdade racial
B13: 0001 | C13: 2026 | D13: Despesas correntes | E13: FIAR - FIAR Novos cursos na EVG (Escola Virtual de Governo) - atendimento ao público | F13: 21290.001685/2026-19 | G13: DAMGI | H13: Ana Carolina | I13: TEDinho | K13: ENAP | P13: Planejamento | Q13: - | R13: 19/10/26: Checklist de Instrução Mínima Obrigatória (65171082); 13/10/26: Despacho (64245486) Manifestação de Interesse; 21/09/26: Despacho(64245486) envio do Ofício Manifestação de Interesse; 08/09/26: Ofício (64213089)Manifestação de Interesse para o devido acompanhamento; 31/08/26: Ofício Gab (63650358) a ser assinado; 10/08/26: Despacho DAMGI (63449289), a ser assinado, encaminhando Minuta de Ofício sobre descentralização de créditos entre MIR e Enap no âmbito do FIAR; 03/08/26:Novos cursos EVG: Parcerias com a Diretoria de Desenvolvimento Profissional DDPro-Enap. Ainda não enviado para ENAP. 13/07/26 Ações do FIAR, processo iniciado. Novos cursos EVG | S13: 0400 - Formação de gestores públicos para promoção da igualdade racial
B14: 0001 | C14: 2025 | D14: Despesas correntes | E14: FIAR ENAP - Vagas para servidores negros do Sinapir em MBA em gestão pública | F14: 21290.001553/2025-06 | G14: DAMGI | H14: Ana Carolina | I14: TEDinho | K14: ENAP | L14: 55566.42 | M14: 38945.56 | N14: 24278.39 | O14: 24278.39 | P14: Aguardando Empenho | Q14: - | R14: 19/10/26: Relatório parcial prestação de contas (63783310); 17/08/26: e-mail (61462875) sobre vagas remananescentes em 29/04/26; 27/07/26: repassado o financeiro em janeiro/2026 (SEI 57424120). 2026NC0000044 (57172406) emitida em janeiro/2026 corresponde à última parcela do TED. 22/12/2025: TED em execução. Conforme apostilamento (SEI 55813777), após a assinatura foi descentralizado o valor R$ 19.579,72 (SEI 55666534). | S14: 0400 - Formação de gestores públicos para promoção da igualdade racial
B15: 0001 | C15: 2025 | D15: Despesas correntes | E15: TED UNB - Casa da Igualdade Racial (disseminação do apoio aos Núcleos de prática jurídica e outros serviços voltados para a Casa) | F15: 21290.004151/2025-55 | G15: DAMGI | H15: Ana Carolina | I15: TED | K15: UNB | P15: Instrução Processual | Q15: - | R15: 19/10/26: Despacho(56580718)encaminhamento do Ofício 18096 (56518582) à UnB; 13/10/26: Redução do valor programado de R$ 2,9 mi para R$ 0,00. Aguardando resposta da UNB, desde dezembro/2025, ao OFÍCIO SEI Nº 18096/2025/MIR 56518582. Plano de trabalho, em análise na DAMGI/CGAGC. Realizadas reuniões com SEA e DAMGI/MIR, para fortalecimento da Casa da Igualdade Racial. Solicitação de Manifestação de interesse encaminhada ao Gabinete SENAPIR em 09/12/2025 - (SEI 56182188). O TED objetiva apoiar núcleos de pesquisa e extensão no desenvolvimento de ações nas Casas de Igualdade de Racial. A ação proposta tem foco no fortalecimento do atendimento multidisciplinar à vítima de racismo, abrangendo suporte jurídico, psicossocial e ações de promoção da igualdade racial, alinhadas às políticas públicas do Governo Federal e às atribuições desde Ministério. | S15: 2071 - Observatório de monitoramento e avaliação do SINAPIR
B16: 0001 | C16: 2026 | D16: Despesas correntes | E16: Projetos Redes – TEDs com IFES das cinco regiões, a partir de chamamento público; | F16: 21290.200112/2024-04 | G16: DAMGI | H16: Tatiana | I16: TED | K16: Diversos | P16: Instrução Processual | Q16: - | R16: 19/10/26: memória de reunião(50682620) em 13/05/2025; 17/08/26: encaminhado o Ofício 18096 (56518582) à Universidade de Brasília em 23/12/25; 27/07/26: Exclusão do valor programado. 22/06/2026: Edital em elaboração. Ver com a Tatiana | S16: 2071 - Observatório de monitoramento e avaliação do SINAPIR
B17: 0001 | C17: 2025 | D17: Despesas correntes | E17: TED - UFF sobre orçamento público de igualdade racial. | F17: 21290.000123/2026-40 | G17: DAMGI | H17: Luciano Silva | I17: TED | K17: UFF | P17: Instrução Processual | Q17: - | R17: 19/10/26: Ofício Gab SENAPIR(62878427) a ser assinado; 10/08/26: Despacho DAMGI (62721938)defeso eleitoral em 09/07/26; 06/07/26: Exclusão do valor programado na JEO. Está em análise, teve o valor global reduzido; 22/06/26: Despacho DAMGI 62147714 encaminhando ao Gabinete; 28/5 - Conclusão dos ajustes em PT para envio ao Gabinete SENAPIR. 06/04/2026: Processo em Instrução processual. enviado à UFF OFÍCIO SEI Nº 2677/2026/MIR em 03/03/2026 ainda sem resposta | S17: 2071 - Observatório de monitoramento e avaliação do SINAPIR
B18: 0001 | C18: 2025 | D18: Despesas correntes | E18: TED - UFF CERD | F18: 21290.000127/2026-28 | G18: DAMGI | H18: Luciano Silva | I18: TED | K18: UFF | L18: 204000 | M18: 204000 | N18: 179520 | O18: 179520 | P18: Empenhado | Q18: junho | R18: 19/10/26: e-mail (65170666) informando a liberação da programação financeira a UFF; 13/10/26:Despacho(64692938) Resposta sobre a indicação de Gestor de Parceria responsável pelo acompanhamento. Publicação; 21/09/26: Ofício (64547093) a ser assinado; 14/09/26: Despacho(63811282) Descentralização orçamentária R$ 204.000,00; 17/07/26: Despacho DAMGI(63659507) ao Gab indicação de gestores titular e suplente; 10/08/26: Extrato de publicação do tedinho(63489682); 07/08/26: e-mail (63276521) Extrato da Descentralização de crédito - MIR X UFF; 27/07/26: Despacho(62948635) Certificação de Disponibilidade; 20/07/26: Despacho DGA (62947323) autorização prévia; 13/07/26: Despacho (62817387)defeso eleitoral; 06/07/26: Ajustes realizados e reenvio para SE/MIR em 02/06 (61811202). Instrução completa enviada para SE/MIR em 22/05 - SEI 61467420 | S18: 2071 - Observatório de monitoramento e avaliação do SINAPIR
B19: 0001 | C19: 2025 | D19: Despesas correntes | E19: ADITIVO - GTMapir Desenvolvimento de avaliações e consultorias voltadas à políticas prioritárias do GTMAPIR | F19: 21290.001930/2025-07 | G19: DAMGI | H19: Tatiana | I19: TEDinho | K19: ENAP | P19: Planejamento | Q19: - | R19: 19/10/26: e-mail(64868367) Solicitação de Pretação de contas em 1/10/26; 28/09/26: Nota Técnica(62806366)Avaliação técnica dos produtos finais (Enap); 21/09/26: Despacho Gab SENAPIR(62882663) fim de vigência em 03/06/26; 13/07/26: Nota Técnica (62806366) Avaliação técnica dos produtos finais; 06/07/26:Despacho Gab. SENAPIR (60551170) Comunicação de fim de vigência; 26/05/2026: Em discussão com ENAP, objetivo é processo de Avaliação ex-post dos demais programas estratégicos do MIR. 235.000,00 | S19: 2071 - Observatório de monitoramento e avaliação do SINAPIR
B20: 0001 | C20: 2026 | D20: Despesas correntes | E20: Seminário - Apresentação de pesquisas e política públicas | G20: DAMGI | H20: Tatiana | I20: TEDinho | L20: 60000 | P20: Planejamento | Q20: - | R20: 22/12/2025: Objetiva-se a realização de Encontro com pesquisadores ligados às estratégias do MIR de apoio a NEABs e pesquisas para fortalecimento do SINAPIR. | S20: 2071 - Observatório de monitoramento e avaliação do SINAPIR
B21: 0001 | C21: 2026 | D21: Despesas correntes | E21: FIAR - FIAR ENAP aqui - 12 turmas (Incluindo Casa da Igualdade Racial) | F21: 21290.002084/2025-34 | G21: DAMGI | H21: Ana Carolina | I21: Tedinho | K21: ENAP | L21: 66809.2 | P21: Aguardando Empenho | Q21: - | R21: 19/10/26: Ofício Gab SENAPIR(65019655) a ser assinado; 05/10/26: Despacho DAMGI(64807894) a ser assinado; 28/09/26: Ofício(64464215) Resposta sobre o Programa “Enap Aqui Igualdade Racial: Estratégias de Implementação Local”; 14/09/26:Despacho(64258697)Indicação de localidades para realização das oficinas Enap Aqui08/09/26: Despacho(64145388)Indicação de localidades para realização das oficinas Enap Aqui – Igualdade Racial: Estratégias de Implementação Local; 31/08/26: Despacho(63912851) com a Nota Informativa SEI nº 461/2026/MIR (SEI nº 63903572), que trata do andamento do programa “Enap Aqui Igualdade Racial; 24/08/26: Despacho (63846784)indicação de estados e municípios para realização de novas edições da Oficina Enap Aqui; 17/08/26: Despacho Gab(63394096)Convite para participação na abertura das Oficinas "Enap Aqui" em 06/08/26; 03/08/26: E-mail (62315453) Divulgação e apoio à mobilização para participação na Oficina "Enap Aqui! Igualdade Racial: Estratégias de Implementação Local". Ofício (62306196) 29/06/26: Nota Jurídica 62195996. não se enquadram nas proibições legais, desde que as ações efetivamente desenvolvidas se mantenham dentro do espectro meramente técnico-acadêmico, congruentes com o Programa Enap Aqui; 26/05/2026: em abril/2026 Nota de Crédito 192 (SEI 60964125)15/04/2026: aguardando assinatura pelo MIR e pela instituição para posterior publicação. 07/04/2026: Manifestação de interesse enviada (SEI 52329757). Em 01 e 02 de dezembro/2025, foi realizado projeto piloto em parceria com a SEPROMI/BA. (59699323) Certificação de Disponibilidade Orçamentária. | S21: 0400 - Formação de gestores públicos para promoção da igualdade racial
B22: 0001 | C22: 2026 | D22: Despesas correntes | E22: FIAR - FIAR Cátedras Negras | F22: 21290.002144/2026-08 | G22: DAMGI | H22: Luciano Goes | I22: Tedinho | K22: ENAP | P22: Instrução Processual | Q22: julho | R22: 19/10/26: Despacho(62540214) encaminhamento de Manifestação de Interesse à ENAP no dia 30/06/26; 17/08/26: Manifestação de interesse Ofício (62495465) em 01/07/26; 29/06/26: Ofício 62051569 Plano de Trabalho Execução Descentralizada entre MIR e ENAP encaminhado a SE. Em diálogo com ENAP, para PT. Concluindo instrução para envio de Manifestação de Interesse
B23: 0001 | C23: 2026 | D23: Despesas correntes | E23: Apoio técnico aos entes SINAPIR | G23: DAMGI | H23: Ana Carolina | I23: TED | P23: Planejamento | Q23: - | R23: 22/12/2025: Tem como objetivo instituir coordenação de pesquisadores ligados às estratégias do MIR de apoio a NEABs e pesquisas para fortalecimento do SINAPIR. Ver com Ana Carolina | S23: 0400 - Formação de gestores públicos para promoção da igualdade racial
B24: 0001 | C24: 2026 | D24: Despesas correntes | E24: FIAR - Evidências express | G24: DAMGI | H24: Ana Carolina | I24: Tedinho | K24: ENAP | P24: Planejamento | Q24: - | S24: 0400 - Formação de gestores públicos para promoção da igualdade racial
B25: 0001 | C25: 2026 | D25: Despesas correntes | E25: TED UNB - COPENE | F25: 21290.001227/2026-71 | G25: Gabinete/DAMGI | H25: Luciano Silva | I25: TED | K25: UNB | L25: 240000 | M25: 240000 | N25: 240000 | O25: 240000 | P25: Pago/Liquidado | Q25: junho | R25: 19/10/26:Roteiro(65081105) PROGRAMAÇÃO COMPLETA; 05/10/26 Ofício(64473211) Publicação da designação de gestores do TED Nº 14/2026; 14/09/26: Despacho DGA(63355674) indicação de gestores; 03/08/26: Despacho (63247545) indicação de gestores; 27/07/26: Despacho(63130733) Termo de Execução Descentralizada nº 14/2026 - MIR X UnB; 20/07/26: NC e PF emitidas; 13/07/26: Aguardando a assinatura da Ministra. TED(62745335)
B26: 0001 | C26: 2026 | D26: Despesas correntes | E26: Material Gráfico | F26: 21290.000732/2025-18 | G26: DAMGI | K26: MGI | L26: 8557.77 | M26: 7251.06 | N26: 7251.06 | O26: 7251.06 | P26: Pago/Liquidado | Q26: - | R26: 19/10/26: Valores de despesas administrativas; 22/06/26. Verificar com a Luciana Rangel outros valores que foram empenhados no PO 0001 DAMGI: UFPR R$ 1.196,38; MGI R$ 4.154,96 | S26: 0400 - Formação de gestores públicos para promoção da igualdade racial
B27: 0002 | C27: 2026 | D27: Despesas correntes | E27: Casa da Igualdade Racial 2 + Inclusão Produtiva | F27: 21290.002082/2026-26 | G27: DAMGI | H27: Edvânio Macedo | R27: 19/10/26: Ofício (62031616)manifestou seu interesse em estabelecer parceria com esse Ministério
B28: 0002 | C28: 2026 | D28: Despesas correntes | E28: Casa da Igualdade Racial 2 + Inclusão Produtiva | F28: 21290.002082/2026-26 | G28: DAI | H28: Edvânio Macedo | I28: TED | K28: FIOCRUZ | L28: 5500000.5 | P28: Planejamento | Q28: - | R28: Sem decisão técnica e política sobre a tramitação processual do instrumento adequado. A IN está em discussão interna.
B29: 0002 | C29: 2026 | D29: Despesas correntes | E29: Agentes 2 e Xica 1 | F29: 21290.002528/2025-31 | G29: DAI | H29: Edvânio Macedo | I29: TED | K29: UFRB | L29: 1541605.9 | M29: 1541605.9 | N29: 1541605.9 | P29: Empenhado | Q29: junho
B30: 0002 | C30: 2026 | D30: Despesas correntes | E30: Incubadora do Afroturismo/Rotas Negras/Centro de Estudos Estratégicos | F30: 21290.000354/2026-53 | G30: DAI | H30: Edvânio Macedo | I30: TED | K30: UFSM | L30: 5710000 | M30: 5710000 | N30: 5710000 | O30: 5710000 | P30: Pago/Liquidado | Q30: junho
B31: 0002 | C31: 2026 | D31: Despesas correntes | E31: PAS Periferias Urbanas e Racismo Ambiental - SINAPIR pelo Clima | F31: 21290.004107/2025-45 | G31: DAI | H31: Edvânio Macedo | I31: TED | K31: UFMA | L31: 980332.52 | P31: Planejamento | Q31: - | R31: Retornou para Gabin da SENAPIR com ajustes, a UFMA está realizando os últimos ajustes do plano de trabalho.
B32: 0002 | C32: 2026 | D32: Despesas correntes | E32: Fortalecimento a Cadeia Produtiva do Carnaval/Trabalhadores | F32: 21290.001137/2026-81 | G32: DAI | H32: Edvânio Macedo | I32: TED | K32: UFF | L32: 3200000 | M32: 3200000 | N32: 2944000 | O32: 2944000 | P32: Pago/Liquidado | Q32: junho
B33: 0002 | C33: 2026 | D33: Despesas correntes | E33: Aditivo Fiocruz - Casas, Flilio | F33: 21290.002700/2025-57 | G33: DAI | H33: Edvânio Macedo | I33: TED | K33: FIOCRUZ | L33: 1216094.3 | P33: Planejamento | Q33: - | R33: Aguardando a Fiocruz enviar formalmente o PT e Ofício assinado
